<?xml version="1.0" ?>
<!-- =================================================================================== -->
<!-- |    This document was autogenerated by xacro from src/da_vinci_tool_integration/urdf/med7.xacro | -->
<!-- |    EDITING THIS FILE BY HAND IS NOT RECOMMENDED                                 | -->
<!-- =================================================================================== -->
<!-- top level -->
<robot name="med7attached">
  <!-- KDL requires a link without inertia / Gazebo requires a connection to world link or robot
    will tipple https://github.com/lbr-stack/lbr_fri_ros2_stack/issues/230 -->
  <link name="world"/>
  <!--joint
        between <robot_name>_world_link and robot_name_link_0-->
  <joint name="lbr_world_joint" type="fixed">
    <parent link="world"/>
    <child link="lbr_link_0"/>
  </joint>
  <!-- ros_control-plugin -->
  <gazebo>
    <plugin filename="gz_ros2_control-system" name="gz_ros2_control::GazeboSimROS2ControlPlugin">
      <parameters>/home/suphasitpp/my_msc_ws/install/lbr_description/share/lbr_description/ros2_control/lbr_controllers.yaml</parameters>
      <ros>
        <namespace>/lbr</namespace>
      </ros>
    </plugin>
  </gazebo>
  <gazebo reference="lbr_link_0">
    <mu1>0.2</mu1>
    <mu2>0.2</mu2>
  </gazebo>
  <gazebo reference="lbr_A1">
    <implicitSpringDamper>true</implicitSpringDamper>
    <provideFeedback>true</provideFeedback>
  </gazebo>
  <gazebo reference="lbr_link_1">
    <mu1>0.2</mu1>
    <mu2>0.2</mu2>
  </gazebo>
  <gazebo reference="lbr_A2">
    <implicitSpringDamper>true</implicitSpringDamper>
    <provideFeedback>true</provideFeedback>
  </gazebo>
  <gazebo reference="lbr_link_2">
    <mu1>0.2</mu1>
    <mu2>0.2</mu2>
  </gazebo>
  <gazebo reference="lbr_A3">
    <implicitSpringDamper>true</implicitSpringDamper>
    <provideFeedback>true</provideFeedback>
  </gazebo>
  <gazebo reference="lbr_link_3">
    <mu1>0.2</mu1>
    <mu2>0.2</mu2>
  </gazebo>
  <gazebo reference="lbr_A4">
    <implicitSpringDamper>true</implicitSpringDamper>
    <provideFeedback>true</provideFeedback>
  </gazebo>
  <gazebo reference="lbr_link_4">
    <mu1>0.2</mu1>
    <mu2>0.2</mu2>
  </gazebo>
  <gazebo reference="lbr_A5">
    <implicitSpringDamper>true</implicitSpringDamper>
    <provideFeedback>true</provideFeedback>
  </gazebo>
  <gazebo reference="lbr_link_5">
    <mu1>0.2</mu1>
    <mu2>0.2</mu2>
  </gazebo>
  <gazebo reference="lbr_A6">
    <implicitSpringDamper>true</implicitSpringDamper>
    <provideFeedback>true</provideFeedback>
  </gazebo>
  <gazebo reference="lbr_link_6">
    <mu1>0.2</mu1>
    <mu2>0.2</mu2>
  </gazebo>
  <gazebo reference="lbr_A7">
    <implicitSpringDamper>true</implicitSpringDamper>
    <provideFeedback>true</provideFeedback>
  </gazebo>
  <gazebo reference="lbr_link_7">
    <mu1>0.2</mu1>
    <mu2>0.2</mu2>
  </gazebo>
  <ros2_control name="lbr_system_interface" type="system">
    <joint name="lbr_A1">
      <command_interface name="position">
        <param name="min">-2.9670597283903604</param>
        <param name="max">2.9670597283903604</param>
      </command_interface>
      <command_interface name="effort">
        <param name="min">-200</param>
        <param name="max"> 200</param>
      </command_interface>
      <state_interface name="position">
        <param name="initial_value">0.0</param>
      </state_interface>
      <state_interface name="velocity"/>
      <state_interface name="effort"/>
    </joint>
    <joint name="lbr_A2">
      <command_interface name="position">
        <param name="min">-2.0943951023931953</param>
        <param name="max">2.0943951023931953</param>
      </command_interface>
      <command_interface name="effort">
        <param name="min">-200</param>
        <param name="max"> 200</param>
      </command_interface>
      <state_interface name="position">
        <param name="initial_value">0.4363323129985824</param>
      </state_interface>
      <state_interface name="velocity"/>
      <state_interface name="effort"/>
    </joint>
    <joint name="lbr_A3">
      <command_interface name="position">
        <param name="min">-2.9670597283903604</param>
        <param name="max">2.9670597283903604</param>
      </command_interface>
      <command_interface name="effort">
        <param name="min">-200</param>
        <param name="max"> 200</param>
      </command_interface>
      <state_interface name="position">
        <param name="initial_value">0.0</param>
      </state_interface>
      <state_interface name="velocity"/>
      <state_interface name="effort"/>
    </joint>
    <joint name="lbr_A4">
      <command_interface name="position">
        <param name="min">-2.0943951023931953</param>
        <param name="max">2.0943951023931953</param>
      </command_interface>
      <command_interface name="effort">
        <param name="min">-200</param>
        <param name="max"> 200</param>
      </command_interface>
      <state_interface name="position">
        <param name="initial_value">1.5707963267948966</param>
      </state_interface>
      <state_interface name="velocity"/>
      <state_interface name="effort"/>
    </joint>
    <joint name="lbr_A5">
      <command_interface name="position">
        <param name="min">-2.9670597283903604</param>
        <param name="max">2.9670597283903604</param>
      </command_interface>
      <command_interface name="effort">
        <param name="min">-200</param>
        <param name="max"> 200</param>
      </command_interface>
      <state_interface name="position">
        <param name="initial_value">0.0</param>
      </state_interface>
      <state_interface name="velocity"/>
      <state_interface name="effort"/>
    </joint>
    <joint name="lbr_A6">
      <command_interface name="position">
        <param name="min">-2.0943951023931953</param>
        <param name="max">2.0943951023931953</param>
      </command_interface>
      <command_interface name="effort">
        <param name="min">-200</param>
        <param name="max"> 200</param>
      </command_interface>
      <state_interface name="position">
        <param name="initial_value">0.0</param>
      </state_interface>
      <state_interface name="velocity"/>
      <state_interface name="effort"/>
    </joint>
    <joint name="lbr_A7">
      <command_interface name="position">
        <param name="min">-3.0543261909900763</param>
        <param name="max">3.0543261909900763</param>
      </command_interface>
      <command_interface name="effort">
        <param name="min">-200</param>
        <param name="max"> 200</param>
      </command_interface>
      <state_interface name="position">
        <param name="initial_value">0.0</param>
      </state_interface>
      <state_interface name="velocity"/>
      <state_interface name="effort"/>
    </joint>
  </ros2_control>
  <!-- properties -->
  <link name="lbr_link_0">
    <inertial>
      <origin rpy="0 0 0" xyz="-0.001896 0.0 0.076263"/>
      <mass value="7.143112"/>
      <inertia ixx="0.038694" ixy="0.0" ixz="-0.000686" iyy="0.039461" iyz="0.0" izz="0.054387"/>
    </inertial>
    <visual>
      <origin rpy="0 0 0" xyz="0 0 0"/>
      <geometry>
        <mesh filename="package://lbr_description/meshes/med7/visual/link_0.dae"/>
      </geometry>
    </visual>
    <collision>
      <origin rpy="0 0 0" xyz="0 0 0"/>
      <geometry>
        <mesh filename="package://lbr_description/meshes/med7/collision/link_0.stl"/>
      </geometry>
    </collision>
  </link>
  <joint name="lbr_A1" type="revolute">
    <origin rpy="0 0 0" xyz="0.0 0.0 0.1475"/>
    <parent link="lbr_link_0"/>
    <child link="lbr_link_1"/>
    <axis xyz="0.0 0.0 1.0"/>
    <limit effort="200" lower="-2.9670597283903604" upper="2.9670597283903604" velocity="1.710422666954443"/>
    <dynamics damping="10.0" friction="0.1"/>
  </joint>
  <link name="lbr_link_1">
    <inertial>
      <origin rpy="0 0 0" xyz="0.0 -0.034819  0.123299"/>
      <mass value="3.271499"/>
      <inertia ixx="0.020611" ixy="0.0" ixz="0.0" iyy="0.019667" iyz="0.00366" izz="0.00729"/>
    </inertial>
    <visual>
      <origin rpy="0 0 0" xyz="0.0 0.0 -0.1475"/>
      <geometry>
        <mesh filename="package://lbr_description/meshes/med7/visual/link_1.dae"/>
      </geometry>
    </visual>
    <collision>
      <origin rpy="0 0 0" xyz="0.0 0.0 -0.1475"/>
      <geometry>
        <mesh filename="package://lbr_description/meshes/med7/collision/link_1.stl"/>
      </geometry>
    </collision>
  </link>
  <joint name="lbr_A2" type="revolute">
    <origin rpy="0 0 0" xyz="0.0 -0.0105 0.1925"/>
    <parent link="lbr_link_1"/>
    <child link="lbr_link_2"/>
    <axis xyz="0.0 1.0 0.0"/>
    <limit effort="200" lower="-2.0943951023931953" upper="2.0943951023931953" velocity="1.710422666954443"/>
    <dynamics damping="10.0" friction="0.1"/>
  </joint>
  <link name="lbr_link_2">
    <inertial>
      <origin rpy="0 0 0" xyz="0.0 0.039793 0.086944"/>
      <mass value="3.886413"/>
      <inertia ixx="0.030552" ixy="0.0" ixz="0.0" iyy="0.028995" iyz="0.005676" izz="0.009317"/>
    </inertial>
    <visual>
      <origin rpy="0 0 0" xyz="0.0 0.0105 -0.34"/>
      <geometry>
        <mesh filename="package://lbr_description/meshes/med7/visual/link_2.dae"/>
      </geometry>
    </visual>
    <collision>
      <origin rpy="0 0 0" xyz="0.0 0.0105 -0.34"/>
      <geometry>
        <mesh filename="package://lbr_description/meshes/med7/collision/link_2.stl"/>
      </geometry>
    </collision>
  </link>
  <joint name="lbr_A3" type="revolute">
    <origin rpy="0 0 0" xyz="0.0 0.0105 0.2075"/>
    <parent link="lbr_link_2"/>
    <child link="lbr_link_3"/>
    <axis xyz="0.0 0.0 1.0"/>
    <limit effort="200" lower="-2.9670597283903604" upper="2.9670597283903604" velocity="1.7453292519943295"/>
    <dynamics damping="10.0" friction="0.1"/>
  </joint>
  <link name="lbr_link_3">
    <inertial>
      <origin rpy="0 0 0" xyz="0.0 0.034819  0.123299"/>
      <mass value="3.271499"/>
      <inertia ixx="0.020611" ixy="0.0" ixz="0.0" iyy="0.019667" iyz="-0.00366" izz="0.00729"/>
    </inertial>
    <visual>
      <origin rpy="0 0 0" xyz="0.0 0.0 -0.5475"/>
      <geometry>
        <mesh filename="package://lbr_description/meshes/med7/visual/link_3.dae"/>
      </geometry>
    </visual>
    <collision>
      <origin rpy="0 0 0" xyz="0.0 0.0 -0.5475"/>
      <geometry>
        <mesh filename="package://lbr_description/meshes/med7/collision/link_3.stl"/>
      </geometry>
    </collision>
  </link>
  <joint name="lbr_A4" type="revolute">
    <origin rpy="0 0 0" xyz="0.0 0.0105 0.1925"/>
    <parent link="lbr_link_3"/>
    <child link="lbr_link_4"/>
    <axis xyz="0.0 -1.0 0.0"/>
    <limit effort="200" lower="-2.0943951023931953" upper="2.0943951023931953" velocity="2.2689280275926285"/>
    <dynamics damping="10.0" friction="0.1"/>
  </joint>
  <link name="lbr_link_4">
    <inertial>
      <origin rpy="0 0 0" xyz="0.0 -0.039793  0.086944"/>
      <mass value="3.886411"/>
      <inertia ixx="0.030547" ixy="0.0" ixz="0.0" iyy="0.028993" iyz="-0.005676" izz="0.009313"/>
    </inertial>
    <visual>
      <origin rpy="0 0 0" xyz="0.0 -0.0105 -0.74"/>
      <geometry>
        <mesh filename="package://lbr_description/meshes/med7/visual/link_4.dae"/>
      </geometry>
    </visual>
    <collision>
      <origin rpy="0 0 0" xyz="0.0 -0.0105 -0.74"/>
      <geometry>
        <mesh filename="package://lbr_description/meshes/med7/collision/link_4.stl"/>
      </geometry>
    </collision>
  </link>
  <joint name="lbr_A5" type="revolute">
    <origin rpy="0 0 0" xyz="0.0 -0.0105 0.2075"/>
    <parent link="lbr_link_4"/>
    <child link="lbr_link_5"/>
    <axis xyz="0.0 0.0 1.0"/>
    <limit effort="200" lower="-2.9670597283903604" upper="2.9670597283903604" velocity="2.443460952792061"/>
    <dynamics damping="10.0" friction="0.1"/>
  </joint>
  <link name="lbr_link_5">
    <inertial>
      <origin rpy="0 0 0" xyz="0.0 -0.029824 0.076267"/>
      <mass value="1.474048"/>
      <inertia ixx="0.008179" ixy="0.0" ixz="0.0" iyy="0.006879" iyz="0.002704" izz="0.003709"/>
    </inertial>
    <visual>
      <origin rpy="0 0 0" xyz="0.0 0.0 -0.9475"/>
      <geometry>
        <mesh filename="package://lbr_description/meshes/med7/visual/link_5.dae"/>
      </geometry>
    </visual>
    <collision>
      <origin rpy="0 0 0" xyz="0.0 0.0 -0.9475"/>
      <geometry>
        <mesh filename="package://lbr_description/meshes/med7/collision/link_5.stl"/>
      </geometry>
    </collision>
  </link>
  <joint name="lbr_A6" type="revolute">
    <origin rpy="0 0 0" xyz="0.0 -0.0707 0.1925"/>
    <parent link="lbr_link_5"/>
    <child link="lbr_link_6"/>
    <axis xyz="0.0 1.0 0.0"/>
    <limit effort="200" lower="-2.0943951023931953" upper="2.0943951023931953" velocity="3.141592653589793"/>
    <dynamics damping="10.0" friction="0.1"/>
  </joint>
  <link name="lbr_link_6">
    <inertial>
      <origin rpy="0 0 0" xyz="-1.000e-06 7.102e-02 4.953e-03"/>
      <mass value="2.316911"/>
      <inertia ixx="0.006813" ixy="0.0" ixz="0.0" iyy="0.006559" iyz="0.0003" izz="0.004462"/>
    </inertial>
    <visual>
      <origin rpy="0 0 0" xyz="0.0 0.0707 -1.14"/>
      <geometry>
        <mesh filename="package://lbr_description/meshes/med7/visual/link_6.dae"/>
      </geometry>
    </visual>
    <collision>
      <origin rpy="0 0 0" xyz="0.0 0.0707 -1.14"/>
      <geometry>
        <mesh filename="package://lbr_description/meshes/med7/collision/link_6.stl"/>
      </geometry>
    </collision>
  </link>
  <joint name="lbr_A7" type="revolute">
    <origin rpy="0 0 0" xyz="0.0 0.0707 0.091"/>
    <parent link="lbr_link_6"/>
    <child link="lbr_link_7"/>
    <axis xyz="0.0 0.0 1.0"/>
    <limit effort="200" lower="-3.0543261909900763" upper="3.0543261909900763" velocity="3.141592653589793"/>
    <dynamics damping="10.0" friction="0.1"/>
  </joint>
  <link name="lbr_link_7">
    <inertial>
      <origin rpy="0 0 0" xyz="3.0000e-06 -2.0000e-06 1.3782e-02"/>
      <mass value="0.250108"/>
      <inertia ixx="0.000165" ixy="0.0" ixz="0.0" iyy="0.000165" iyz="0.0" izz="0.000288"/>
    </inertial>
    <visual>
      <origin rpy="0 0 0" xyz="0.0 0.0 -1.231"/>
      <geometry>
        <mesh filename="package://lbr_description/meshes/med7/visual/link_7.dae"/>
      </geometry>
    </visual>
    <collision>
      <origin rpy="0 0 0" xyz="0.0 0.0 -1.231"/>
      <geometry>
        <mesh filename="package://lbr_description/meshes/med7/collision/link_7.stl"/>
      </geometry>
    </collision>
  </link>
  <joint name="lbr_joint_ee" type="fixed">
    <parent link="lbr_link_7"/>
    <child link="lbr_link_ee"/>
    <origin rpy="0 0 0" xyz="0 0 0.035"/>
  </joint>
  <link name="lbr_link_ee">
        </link>
  <link name="base_link">
    <visual>
      <geometry>
        <mesh filename="package://da_vinci_tool_integration/urdf/adaptor/meshes/Da_vinci_si_manipulator.stl" scale="0.001 0.001 0.001"/>
      </geometry>
      <material name="grey">
        <color rgba="0.7 0.7 0.7 1.0"/>
      </material>
    </visual>
    <collision>
      <geometry>
        <mesh filename="package://da_vinci_tool_integration/urdf/adaptor/meshes/Da_vinci_si_manipulator.stl" scale="0.001 0.001 0.001"/>
      </geometry>
    </collision>
  </link>
  <!-- Link 3: Tool Main Link -->
  <link name="PSM_tool_main_link">
    <visual>
      <origin rpy="0 0 1.5707963267948966" xyz="0 0 0.041"/>
      <geometry>
        <mesh filename="package://psm_description/meshes/Classic/tool_main.stl"/>
      </geometry>
    </visual>
    <collision>
      <origin rpy="0 0 1.5707963267948966" xyz="0 0 0.041"/>
      <geometry>
        <mesh filename="package://psm_description/meshes/Classic/tool_main.stl"/>
      </geometry>
    </collision>
  </link>
  <!-- Link 4: Tool Wrist Link -->
  <link name="PSM_tool_wrist_link">
    <visual>
      <origin rpy="0 0 1.5707963267948966" xyz="0 0 -0.0091"/>
      <geometry>
        <mesh filename="package://psm_description/meshes/Classic/tool_wrist_link.stl"/>
      </geometry>
    </visual>
    <collision>
      <origin rpy="0 0 1.5707963267948966" xyz="0 0 -0.0091"/>
      <geometry>
        <mesh filename="package://psm_description/meshes/Classic/tool_wrist_link.stl"/>
      </geometry>
    </collision>
  </link>
  <!-- Link 4-1: Tool Wrist Shaft Link -->
  <link name="PSM_tool_wrist_shaft_link">
    <visual>
      <origin rpy="1.5707963267948966 0 0" xyz="0 0.00401 0"/>
      <geometry>
        <mesh filename="package://psm_description/meshes/Classic/tool_wrist_shaft_link.stl"/>
      </geometry>
    </visual>
    <collision>
      <origin rpy="1.5707963267948966 0 0" xyz="0 0.00401 0"/>
      <geometry>
        <mesh filename="package://psm_description/meshes/Classic/tool_wrist_shaft_link.stl"/>
      </geometry>
    </collision>
  </link>
  <!-- Joint: Outer Roll Joint: Main to Wrist -->
  <joint name="PSM_outer_roll" type="revolute">
    <parent link="PSM_tool_main_link"/>
    <child link="PSM_tool_wrist_link"/>
    <axis xyz="0 0 1"/>
    <origin rpy="0 0 0" xyz="0 0 0.4162"/>
    <limit effort="1000" lower="-4.53786" upper="4.53786" velocity=".4"/>
  </joint>
  <!-- Joint: Outer Roll Shaft Joint: Wrist to Wrist Shaft -->
  <joint name="PSM_outer_roll_shaft" type="fixed">
    <parent link="PSM_tool_wrist_link"/>
    <child link="PSM_tool_wrist_shaft_link"/>
    <axis xyz="0 0 1"/>
    <origin rpy="0 0 0" xyz="0 0 0.0"/>
  </joint>
  <!-- Link 5: Tool Wrist Sca Link -->
  <link name="PSM_tool_wrist_sca_link">
    <visual>
      <!-- <origin rpy="0 ${PI} 0" xyz="0 0 0"/> -->
      <origin rpy="1.5707963267948966 3.141592653589793 0" xyz="0.0051 0.0032 0"/>
      <geometry>
        <mesh filename="package://psm_description/meshes/Classic/tool_wrist_sca_link.stl"/>
      </geometry>
    </visual>
    <collision>
      <!-- <origin rpy="0 ${PI} 0" xyz="0 0 0"/> -->
      <origin rpy="1.5707963267948966 3.141592653589793 0" xyz="0.0051 0.0032 0"/>
      <geometry>
        <mesh filename="package://psm_description/meshes/Classic/tool_wrist_sca_link.stl"/>
      </geometry>
    </collision>
  </link>
  <!-- Link 6: Tool Wrist Sca Shaft Link -->
  <link name="PSM_tool_wrist_sca_shaft_link">
    <visual>
      <origin rpy="0 0 0" xyz="0 -0.0002 -0.0025"/>
      <geometry>
        <mesh filename="package://psm_description/meshes/Classic/tool_wrist_sca_shaft_link.stl"/>
      </geometry>
    </visual>
    <collision>
      <origin rpy="0 0 0" xyz="0 -0.0002 -0.0025"/>
      <geometry>
        <mesh filename="package://psm_description/meshes/Classic/tool_wrist_sca_shaft_link.stl"/>
      </geometry>
    </collision>
  </link>
  <!-- Link 7-0: Outer Open Angle Virtual Link -->
  <link name="PSM_tool_wrist_sca_ee_link_0">
    <visual>
      <origin rpy="0 0 0" xyz="0 0 0"/>
      <geometry>
        <box size="0 0 0"/>
      </geometry>
    </visual>
    <collision>
      <origin rpy="0 0 0" xyz="0 0 0"/>
      <geometry>
        <box size="0 0 0"/>
      </geometry>
    </collision>
  </link>
  <!-- Link 7-1: Outer Open Angle 1 Link -->
  <link name="PSM_tool_wrist_sca_ee_link_1">
    <visual>
      <origin rpy="0 0 0" xyz="0 0 0"/>
      <geometry>
        <mesh filename="package://psm_description/meshes/Classic/tool_wrist_sca_link_2.stl"/>
      </geometry>
    </visual>
    <collision>
      <origin rpy="0 0 0" xyz="0 0 0"/>
      <geometry>
        <mesh filename="package://psm_description/meshes/Classic/tool_wrist_sca_link_2.stl"/>
      </geometry>
    </collision>
  </link>
  <!-- Link 7-2: Outer Open Angle 2 Link -->
  <link name="PSM_tool_wrist_sca_ee_link_2">
    <visual>
      <origin rpy="0 3.1516 0" xyz="0 0 0"/>
      <geometry>
        <mesh filename="package://psm_description/meshes/Classic/tool_wrist_sca_link_2.stl"/>
      </geometry>
    </visual>
    <collision>
      <origin rpy="0 3.1516 0" xyz="0 0 0"/>
      <geometry>
        <mesh filename="package://psm_description/meshes/Classic/tool_wrist_sca_link_2.stl"/>
      </geometry>
    </collision>
  </link>
  <!-- Link 8: Tool Tip Link -->
  <link name="PSM_tool_tip_link"/>
  <!-- Joint 5: Outer Wrist Pitch Joint: Link 4-1 to Link 5 -->
  <joint name="PSM_outer_wrist_pitch" type="revolute">
    <parent link="PSM_tool_wrist_shaft_link"/>
    <child link="PSM_tool_wrist_sca_link"/>
    <axis xyz="0 0 1"/>
    <origin rpy="-1.5707963267948966 -1.5707963267948966 0" xyz="0 0 0"/>
    <limit effort="1000" lower="-1.5707963267948966" upper="1.5707963267948966" velocity=".4"/>
  </joint>
  <!-- Joint 6: Outer Wrist Yaw Joint: Link 5 to Link 6 -->
  <joint name="PSM_outer_wrist_yaw" type="revolute">
    <parent link="PSM_tool_wrist_sca_link"/>
    <child link="PSM_tool_wrist_sca_shaft_link"/>
    <axis xyz="0 0 1"/>
    <origin rpy="-1.5707963267948966 -1.5707963267948966 0" xyz="0.0091 0 0"/>
    <!-- +/- 80 deg -->
    <limit effort="1000" lower="-1.3963" upper="1.3963" velocity=".4"/>
  </joint>
  <!-- Joint 7-0: Outer Open Angle Joint: Link 6 to Link 7-0 -->
  <joint name="PSM_jaw" type="revolute">
    <parent link="PSM_tool_wrist_sca_shaft_link"/>
    <child link="PSM_tool_wrist_sca_ee_link_0"/>
    <axis xyz="0 0 1"/>
    <origin rpy="0 0 0" xyz="0 0 0"/>
    <limit effort="1000" lower="0" upper="1.5707963267948966" velocity=".4"/>
  </joint>
  <!-- Joint 7-1: Outer Open Angle 1 Joint: Link 6 to Link 7-1 -->
  <joint name="PSM_jaw_mimic_1" type="revolute">
    <parent link="PSM_tool_wrist_sca_shaft_link"/>
    <child link="PSM_tool_wrist_sca_ee_link_1"/>
    <axis xyz="0 0 1"/>
    <origin rpy="0 0 0" xyz="0 0 0"/>
    <limit effort="1000" lower="-1.5707963267948966" upper="1.5707963267948966" velocity=".4"/>
    <mimic joint="PSM_jaw" multiplier="0.5"/>
  </joint>
  <!-- Joint 7-2: Outer Open Angle 2 Joint: Link 6 to Link 7-2 -->
  <joint name="PSM_jaw_mimic_2" type="revolute">
    <parent link="PSM_tool_wrist_sca_shaft_link"/>
    <child link="PSM_tool_wrist_sca_ee_link_2"/>
    <axis xyz="0 0 1"/>
    <origin rpy="0 0 0" xyz="0 0 0"/>
    <limit effort="1000" lower="-1.5707963267948966" upper="1.5707963267948966" velocity=".4"/>
    <mimic joint="PSM_jaw" multiplier="-0.5"/>
  </joint>
  <!-- Joint 7-3: Tool Tip Joint: Link 6 to Link 8 -->
  <joint name="PSM_tool_tip" type="fixed">
    <parent link="PSM_tool_wrist_sca_shaft_link"/>
    <child link="PSM_tool_tip_link"/>
    <origin rpy="0 1.5707963267948966 1.5707963267948966" xyz="0 0.0102 0"/>
  </joint>
  <!-- ROS2 Control -->
  <ros2_control name="PSM_psm_classic_sca_ros2_control" type="system">
    <hardware>
      <plugin>fake_components/GenericSystem</plugin>
    </hardware>
    <!-- Command Joint 0 -->
    <joint name="PSM_outer_yaw">
      <command_interface name="position"/>
      <state_interface name="position"/>
      <state_interface name="velocity"/>
    </joint>
    <!-- Command Joint 1 -->
    <joint name="PSM_pitch">
      <command_interface name="position"/>
      <state_interface name="position"/>
      <state_interface name="velocity"/>
    </joint>
    <!-- Command Joint 2 -->
    <joint name="PSM_outer_insertion">
      <command_interface name="position"/>
      <state_interface name="position"/>
      <state_interface name="velocity"/>
    </joint>
    <!-- Command Joint 3 -->
    <joint name="PSM_outer_roll">
      <command_interface name="position"/>
      <state_interface name="position"/>
      <state_interface name="velocity"/>
    </joint>
    <!-- Mimic Joint 0: Command Joint 1 -->
    <joint name="PSM_outer_pitch_1">
      <state_interface name="position"/>
      <state_interface name="velocity"/>
    </joint>
    <!-- Mimic Joint 1: Command Joint 1 -->
    <joint name="PSM_outer_pitch_2">
      <state_interface name="position"/>
      <state_interface name="velocity"/>
    </joint>
    <!-- Mimic Joint 2: Command Joint 1 -->
    <joint name="PSM_outer_pitch_3">
      <state_interface name="position"/>
      <state_interface name="velocity"/>
    </joint>
    <!-- Mimic Joint 3: Command Joint 1 -->
    <joint name="PSM_outer_pitch_4">
      <state_interface name="position"/>
      <state_interface name="velocity"/>
    </joint>
    <!-- Mimic Joint 4: Command Joint 1 -->
    <joint name="PSM_outer_pitch_5">
      <state_interface name="position"/>
      <state_interface name="velocity"/>
    </joint>
    <!-- Command Joint 0 -->
    <joint name="PSM_outer_wrist_pitch">
      <command_interface name="position"/>
      <state_interface name="position"/>
      <state_interface name="velocity"/>
    </joint>
    <!-- Command Joint 1 -->
    <joint name="PSM_outer_wrist_yaw">
      <command_interface name="position"/>
      <state_interface name="position"/>
      <state_interface name="velocity"/>
    </joint>
    <!-- Command Joint 2 -->
    <joint name="PSM_jaw">
      <command_interface name="position"/>
      <state_interface name="position"/>
      <state_interface name="velocity"/>
    </joint>
    <!-- Mimic Joint 0: Command Joint 2 -->
    <joint name="PSM_jaw_mimic_1">
      <state_interface name="position"/>
      <state_interface name="velocity"/>
    </joint>
    <!-- Mimic Joint 1: Command Joint 2 -->
    <joint name="PSM_jaw_mimic_2">
      <state_interface name="position"/>
      <state_interface name="velocity"/>
    </joint>
  </ros2_control>
  <!-- Joint 1: Connect parent_link (LBR end-effector) to adaptor base_link -->
  <joint name="lbr_to_adaptor" type="fixed">
    <parent link="lbr_link_ee"/>
    <child link="base_link"/>
    <origin rpy="1.5707963267948966 0 0" xyz="0 0 0.02"/>
  </joint>
  <!-- Joint 2: Connect adaptor base_link to PSM base -->
  <joint name="adaptor_to_psm" type="fixed">
    <parent link="base_link"/>
    <child link="PSM_tool_main_link"/>
    <origin rpy="3.141592653589793 0 -1.5707963267948966" xyz="0.0 0.1 -0.01"/>
  </joint>
  <link name="PSM_tool_virtual_tip"/>
  <joint name="virtual_tip_dummy" type="revolute">
    <parent link="PSM_tool_main_link"/>
    <child link="PSM_tool_virtual_tip"/>
    <origin rpy="0 0 0" xyz="0 0 0.4152"/>
    <axis xyz="0 0 1"/>
    <limit effort="0.1" lower="0" upper="0" velocity="0.1"/>
  </joint>
</robot>
